[2024-06-18T14:54:53.945+0000] {local_task_job_runner.py:120} INFO - ::group::Pre task execution logs
[2024-06-18T14:54:53.995+0000] {taskinstance.py:2076} INFO - Dependencies all met for dep_context=non-requeueable deps ti=<TaskInstance: hosp_pipeline.extract_transform_data manual__2024-06-18T14:54:50.180586+00:00 [queued]>
[2024-06-18T14:54:54.012+0000] {taskinstance.py:2076} INFO - Dependencies all met for dep_context=requeueable deps ti=<TaskInstance: hosp_pipeline.extract_transform_data manual__2024-06-18T14:54:50.180586+00:00 [queued]>
[2024-06-18T14:54:54.019+0000] {taskinstance.py:2306} INFO - Starting attempt 1 of 2
[2024-06-18T14:54:54.057+0000] {taskinstance.py:2330} INFO - Executing <Task(PythonOperator): extract_transform_data> on 2024-06-18 14:54:50.180586+00:00
[2024-06-18T14:54:54.071+0000] {warnings.py:110} WARNING - /home/***/.local/lib/python3.12/site-packages/***/task/task_runner/standard_task_runner.py:61: DeprecationWarning: This process (pid=196) is multi-threaded, use of fork() may lead to deadlocks in the child.
  pid = os.fork()

[2024-06-18T14:54:54.076+0000] {standard_task_runner.py:63} INFO - Started process 198 to run task
[2024-06-18T14:54:54.077+0000] {standard_task_runner.py:90} INFO - Running: ['***', 'tasks', 'run', 'hosp_pipeline', 'extract_transform_data', 'manual__2024-06-18T14:54:50.180586+00:00', '--job-id', '13', '--raw', '--subdir', 'DAGS_FOLDER/hospital_dag.py', '--cfg-path', '/tmp/tmpqithp8r3']
[2024-06-18T14:54:54.080+0000] {standard_task_runner.py:91} INFO - Job 13: Subtask extract_transform_data
[2024-06-18T14:54:54.217+0000] {task_command.py:426} INFO - Running <TaskInstance: hosp_pipeline.extract_transform_data manual__2024-06-18T14:54:50.180586+00:00 [running]> on host 51c2a5215f2a
[2024-06-18T14:54:54.478+0000] {taskinstance.py:2648} INFO - Exporting env vars: AIRFLOW_CTX_DAG_OWNER='hospital_admissions' AIRFLOW_CTX_DAG_ID='hosp_pipeline' AIRFLOW_CTX_TASK_ID='extract_transform_data' AIRFLOW_CTX_EXECUTION_DATE='2024-06-18T14:54:50.180586+00:00' AIRFLOW_CTX_TRY_NUMBER='1' AIRFLOW_CTX_DAG_RUN_ID='manual__2024-06-18T14:54:50.180586+00:00'
[2024-06-18T14:54:54.481+0000] {taskinstance.py:430} INFO - ::endgroup::
[2024-06-18T14:54:54.486+0000] {taskinstance.py:441} INFO - ::group::Post task execution logs
[2024-06-18T14:54:54.487+0000] {taskinstance.py:2905} ERROR - Task failed with exception
Traceback (most recent call last):
  File "/home/airflow/.local/lib/python3.12/site-packages/airflow/models/taskinstance.py", line 465, in _execute_task
    result = _execute_callable(context=context, **execute_callable_kwargs)
             ^^^^^^^^^^^^^^^^^^^^^^^^^^^^^^^^^^^^^^^^^^^^^^^^^^^^^^^^^^^^^
  File "/home/airflow/.local/lib/python3.12/site-packages/airflow/models/taskinstance.py", line 432, in _execute_callable
    return execute_callable(context=context, **execute_callable_kwargs)
           ^^^^^^^^^^^^^^^^^^^^^^^^^^^^^^^^^^^^^^^^^^^^^^^^^^^^^^^^^^^^
  File "/home/airflow/.local/lib/python3.12/site-packages/airflow/models/baseoperator.py", line 400, in wrapper
    return func(self, *args, **kwargs)
           ^^^^^^^^^^^^^^^^^^^^^^^^^^^
  File "/home/airflow/.local/lib/python3.12/site-packages/airflow/operators/python.py", line 235, in execute
    return_value = self.execute_callable()
                   ^^^^^^^^^^^^^^^^^^^^^^^
  File "/home/airflow/.local/lib/python3.12/site-packages/airflow/operators/python.py", line 252, in execute_callable
    return self.python_callable(*self.op_args, **self.op_kwargs)
           ^^^^^^^^^^^^^^^^^^^^^^^^^^^^^^^^^^^^^^^^^^^^^^^^^^^^^
  File "/opt/airflow/dags/hospital_dag.py", line 30, in extract_transform
    adm_df = pd.read_csv('source_data/Admission Data.csv')
             ^^^^^^^^^^^^^^^^^^^^^^^^^^^^^^^^^^^^^^^^^^^^^
  File "/home/airflow/.local/lib/python3.12/site-packages/pandas/io/parsers/readers.py", line 948, in read_csv
    return _read(filepath_or_buffer, kwds)
           ^^^^^^^^^^^^^^^^^^^^^^^^^^^^^^^
  File "/home/airflow/.local/lib/python3.12/site-packages/pandas/io/parsers/readers.py", line 611, in _read
    parser = TextFileReader(filepath_or_buffer, **kwds)
             ^^^^^^^^^^^^^^^^^^^^^^^^^^^^^^^^^^^^^^^^^^
  File "/home/airflow/.local/lib/python3.12/site-packages/pandas/io/parsers/readers.py", line 1448, in __init__
    self._engine = self._make_engine(f, self.engine)
                   ^^^^^^^^^^^^^^^^^^^^^^^^^^^^^^^^^
  File "/home/airflow/.local/lib/python3.12/site-packages/pandas/io/parsers/readers.py", line 1705, in _make_engine
    self.handles = get_handle(
                   ^^^^^^^^^^^
  File "/home/airflow/.local/lib/python3.12/site-packages/pandas/io/common.py", line 863, in get_handle
    handle = open(
             ^^^^^
FileNotFoundError: [Errno 2] No such file or directory: 'source_data/Admission Data.csv'
[2024-06-18T14:54:54.510+0000] {taskinstance.py:1206} INFO - Marking task as UP_FOR_RETRY. dag_id=hosp_pipeline, task_id=extract_transform_data, run_id=manual__2024-06-18T14:54:50.180586+00:00, execution_date=20240618T145450, start_date=20240618T145453, end_date=20240618T145454
[2024-06-18T14:54:54.540+0000] {standard_task_runner.py:110} ERROR - Failed to execute job 13 for task extract_transform_data ([Errno 2] No such file or directory: 'source_data/Admission Data.csv'; 198)
[2024-06-18T14:54:54.576+0000] {local_task_job_runner.py:240} INFO - Task exited with return code 1
[2024-06-18T14:54:54.616+0000] {taskinstance.py:3498} INFO - 0 downstream tasks scheduled from follow-on schedule check
[2024-06-18T14:54:54.619+0000] {local_task_job_runner.py:222} INFO - ::endgroup::
