[2024-06-18T10:59:17.488+0000] {local_task_job_runner.py:120} INFO - ::group::Pre task execution logs
[2024-06-18T10:59:17.518+0000] {taskinstance.py:2076} INFO - Dependencies all met for dep_context=non-requeueable deps ti=<TaskInstance: hosp_pipeline.extract_transform_data manual__2024-06-18T10:54:13.922276+00:00 [queued]>
[2024-06-18T10:59:17.525+0000] {taskinstance.py:2076} INFO - Dependencies all met for dep_context=requeueable deps ti=<TaskInstance: hosp_pipeline.extract_transform_data manual__2024-06-18T10:54:13.922276+00:00 [queued]>
[2024-06-18T10:59:17.526+0000] {taskinstance.py:2306} INFO - Starting attempt 2 of 2
[2024-06-18T10:59:17.538+0000] {taskinstance.py:2330} INFO - Executing <Task(PythonOperator): extract_transform_data> on 2024-06-18 10:54:13.922276+00:00
[2024-06-18T10:59:17.547+0000] {warnings.py:110} WARNING - /home/***/.local/lib/python3.12/site-packages/***/task/task_runner/standard_task_runner.py:61: DeprecationWarning: This process (pid=1176) is multi-threaded, use of fork() may lead to deadlocks in the child.
  pid = os.fork()

[2024-06-18T10:59:17.548+0000] {standard_task_runner.py:63} INFO - Started process 1178 to run task
[2024-06-18T10:59:17.548+0000] {standard_task_runner.py:90} INFO - Running: ['***', 'tasks', 'run', 'hosp_pipeline', 'extract_transform_data', 'manual__2024-06-18T10:54:13.922276+00:00', '--job-id', '8', '--raw', '--subdir', 'DAGS_FOLDER/hospital_dag.py', '--cfg-path', '/tmp/tmpl_uq56nz']
[2024-06-18T10:59:17.549+0000] {standard_task_runner.py:91} INFO - Job 8: Subtask extract_transform_data
[2024-06-18T10:59:17.591+0000] {task_command.py:426} INFO - Running <TaskInstance: hosp_pipeline.extract_transform_data manual__2024-06-18T10:54:13.922276+00:00 [running]> on host 51c2a5215f2a
[2024-06-18T10:59:17.665+0000] {taskinstance.py:2648} INFO - Exporting env vars: AIRFLOW_CTX_DAG_OWNER='hospital_admissions' AIRFLOW_CTX_DAG_ID='hosp_pipeline' AIRFLOW_CTX_TASK_ID='extract_transform_data' AIRFLOW_CTX_EXECUTION_DATE='2024-06-18T10:54:13.922276+00:00' AIRFLOW_CTX_TRY_NUMBER='2' AIRFLOW_CTX_DAG_RUN_ID='manual__2024-06-18T10:54:13.922276+00:00'
[2024-06-18T10:59:17.666+0000] {taskinstance.py:430} INFO - ::endgroup::
[2024-06-18T10:59:17.669+0000] {taskinstance.py:441} INFO - ::group::Post task execution logs
[2024-06-18T10:59:17.669+0000] {taskinstance.py:2905} ERROR - Task failed with exception
Traceback (most recent call last):
  File "/home/airflow/.local/lib/python3.12/site-packages/airflow/models/taskinstance.py", line 465, in _execute_task
    result = _execute_callable(context=context, **execute_callable_kwargs)
             ^^^^^^^^^^^^^^^^^^^^^^^^^^^^^^^^^^^^^^^^^^^^^^^^^^^^^^^^^^^^^
  File "/home/airflow/.local/lib/python3.12/site-packages/airflow/models/taskinstance.py", line 432, in _execute_callable
    return execute_callable(context=context, **execute_callable_kwargs)
           ^^^^^^^^^^^^^^^^^^^^^^^^^^^^^^^^^^^^^^^^^^^^^^^^^^^^^^^^^^^^
  File "/home/airflow/.local/lib/python3.12/site-packages/airflow/models/baseoperator.py", line 400, in wrapper
    return func(self, *args, **kwargs)
           ^^^^^^^^^^^^^^^^^^^^^^^^^^^
  File "/home/airflow/.local/lib/python3.12/site-packages/airflow/operators/python.py", line 235, in execute
    return_value = self.execute_callable()
                   ^^^^^^^^^^^^^^^^^^^^^^^
  File "/home/airflow/.local/lib/python3.12/site-packages/airflow/operators/python.py", line 252, in execute_callable
    return self.python_callable(*self.op_args, **self.op_kwargs)
           ^^^^^^^^^^^^^^^^^^^^^^^^^^^^^^^^^^^^^^^^^^^^^^^^^^^^^
  File "/opt/airflow/dags/etl_script.py", line 14, in extract_transform
    adm_df = pd.read_csv('source_data/Admission Data.csv')
             ^^^^^^^^^^^^^^^^^^^^^^^^^^^^^^^^^^^^^^^^^^^^^
  File "/home/airflow/.local/lib/python3.12/site-packages/pandas/io/parsers/readers.py", line 948, in read_csv
    return _read(filepath_or_buffer, kwds)
           ^^^^^^^^^^^^^^^^^^^^^^^^^^^^^^^
  File "/home/airflow/.local/lib/python3.12/site-packages/pandas/io/parsers/readers.py", line 611, in _read
    parser = TextFileReader(filepath_or_buffer, **kwds)
             ^^^^^^^^^^^^^^^^^^^^^^^^^^^^^^^^^^^^^^^^^^
  File "/home/airflow/.local/lib/python3.12/site-packages/pandas/io/parsers/readers.py", line 1448, in __init__
    self._engine = self._make_engine(f, self.engine)
                   ^^^^^^^^^^^^^^^^^^^^^^^^^^^^^^^^^
  File "/home/airflow/.local/lib/python3.12/site-packages/pandas/io/parsers/readers.py", line 1705, in _make_engine
    self.handles = get_handle(
                   ^^^^^^^^^^^
  File "/home/airflow/.local/lib/python3.12/site-packages/pandas/io/common.py", line 863, in get_handle
    handle = open(
             ^^^^^
FileNotFoundError: [Errno 2] No such file or directory: 'source_data/Admission Data.csv'
[2024-06-18T10:59:17.681+0000] {taskinstance.py:1206} INFO - Marking task as FAILED. dag_id=hosp_pipeline, task_id=extract_transform_data, run_id=manual__2024-06-18T10:54:13.922276+00:00, execution_date=20240618T105413, start_date=20240618T105917, end_date=20240618T105917
[2024-06-18T10:59:17.691+0000] {standard_task_runner.py:110} ERROR - Failed to execute job 8 for task extract_transform_data ([Errno 2] No such file or directory: 'source_data/Admission Data.csv'; 1178)
[2024-06-18T10:59:17.722+0000] {local_task_job_runner.py:240} INFO - Task exited with return code 1
[2024-06-18T10:59:17.741+0000] {taskinstance.py:3498} INFO - 0 downstream tasks scheduled from follow-on schedule check
[2024-06-18T10:59:17.746+0000] {local_task_job_runner.py:222} INFO - ::endgroup::
